2023.09.05 11:05
Traceback (most recent call last):
  File "D:\Shapovalov\svoe\Python\PY\Parser6\1_check_new_jobs.py", line 66, in check_new_jobs
    req = requests_upwork.send_request(url_p90, start_url)
  File "D:\Shapovalov\svoe\Python\PY\Parser6\requests_upwork.py", line 197, in send_request
    'Authorization': Token,
UnboundLocalError: local variable 'Token' referenced before assignment

2023.09.05 18:18
Traceback (most recent call last):
  File "D:\Shapovalov\svoe\Python\PY\Parser6\1_check_new_jobs.py", line 75, in check_new_jobs
    jobs_id = db_operations.id_from_db()
  File "D:\Shapovalov\svoe\Python\PY\Parser6\db_operations.py", line 17, in id_from_db
    conn = psycopg.connect(
  File "D:\Shapovalov\svoe\Python\PY\Parser6\python\lib\site-packages\psycopg\connection.py", line 729, in connect
    raise ex.with_traceback(None)
psycopg.OperationalError: connection failed: could not receive data from server: Socket is not connected (0x00002749/10057)
could not send SSL negotiation packet: Socket is not connected (0x00002749/10057)

2023.09.05 18:51
Traceback (most recent call last):
  File "D:\Shapovalov\svoe\Python\PY\Parser6\1_check_new_jobs.py", line 71, in check_new_jobs
    time_start = datetime.now(local)
NameError: name 'local' is not defined

2023-09-06 05:57
1
2023-09-06 06:08
Traceback (most recent call last):
  File "D:\Shapovalov\svoe\Python\PY\Parser6\2_download_jobs.py", line 101, in download_jobs
    jobs = parse_json.downgrade_structure(jobs_cleared)
  File "D:\Shapovalov\svoe\Python\PY\Parser6\parse_json.py", line 248, in downgrade_structure
    print(f'Attention! New keys in job (id = {job["id"]}):')
KeyError: 'id'

2023-09-06 06:10
Traceback (most recent call last):
  File "D:\Shapovalov\svoe\Python\PY\Parser6\2_download_jobs.py", line 101, in download_jobs
    jobs = parse_json.downgrade_structure(jobs_cleared)
  File "D:\Shapovalov\svoe\Python\PY\Parser6\parse_json.py", line 255, in downgrade_structure
    path = PATH(logs_folder, f'{time}.json')
NameError: name 'PATH' is not defined

2023-09-06 06:20
Traceback (most recent call last):
  File "D:\Shapovalov\svoe\Python\PY\Parser6\2_download_jobs.py", line 101, in download_jobs
    jobs = parse_json.downgrade_structure(jobs_cleared)
  File "D:\Shapovalov\svoe\Python\PY\Parser6\parse_json.py", line 332, in downgrade_structure
    print(f'Attention! New keys in job (id = {job["uid"]}):')
KeyError: 'uid'

2023-09-06 06:21
Traceback (most recent call last):
  File "D:\Shapovalov\svoe\Python\PY\Parser6\2_download_jobs.py", line 101, in download_jobs
    jobs = parse_json.downgrade_structure(jobs_cleared)
  File "D:\Shapovalov\svoe\Python\PY\Parser6\parse_json.py", line 335, in downgrade_structure
    dump_json(jobs)
  File "D:\Shapovalov\svoe\Python\PY\Parser6\parse_json.py", line 343, in dump_json
    json.dump(jobs, f)
  File "d:\Shapovalov\svoe\Python\Python38\lib\json\__init__.py", line 179, in dump
    for chunk in iterable:
  File "d:\Shapovalov\svoe\Python\Python38\lib\json\encoder.py", line 429, in _iterencode
    yield from _iterencode_list(o, _current_indent_level)
  File "d:\Shapovalov\svoe\Python\Python38\lib\json\encoder.py", line 325, in _iterencode_list
    yield from chunks
  File "d:\Shapovalov\svoe\Python\Python38\lib\json\encoder.py", line 405, in _iterencode_dict
    yield from chunks
  File "d:\Shapovalov\svoe\Python\Python38\lib\json\encoder.py", line 438, in _iterencode
    o = _default(o)
  File "d:\Shapovalov\svoe\Python\Python38\lib\json\encoder.py", line 179, in default
    raise TypeError(f'Object of type {o.__class__.__name__} '
TypeError: Object of type bytes is not JSON serializable

2023-09-06 06:23
Traceback (most recent call last):
  File "D:\Shapovalov\svoe\Python\PY\Parser6\2_download_jobs.py", line 101, in download_jobs
    jobs = parse_json.downgrade_structure(jobs_cleared)
  File "D:\Shapovalov\svoe\Python\PY\Parser6\parse_json.py", line 335, in downgrade_structure
    dump_json(job)
  File "D:\Shapovalov\svoe\Python\PY\Parser6\parse_json.py", line 343, in dump_json
    json.dump(job, f)
  File "d:\Shapovalov\svoe\Python\Python38\lib\json\__init__.py", line 179, in dump
    for chunk in iterable:
  File "d:\Shapovalov\svoe\Python\Python38\lib\json\encoder.py", line 431, in _iterencode
    yield from _iterencode_dict(o, _current_indent_level)
  File "d:\Shapovalov\svoe\Python\Python38\lib\json\encoder.py", line 405, in _iterencode_dict
    yield from chunks
  File "d:\Shapovalov\svoe\Python\Python38\lib\json\encoder.py", line 438, in _iterencode
    o = _default(o)
  File "d:\Shapovalov\svoe\Python\Python38\lib\json\encoder.py", line 179, in default
    raise TypeError(f'Object of type {o.__class__.__name__} '
TypeError: Object of type bytes is not JSON serializable

2023-09-06 06:30
Traceback (most recent call last):
  File "D:\Shapovalov\svoe\Python\PY\Parser6\2_download_jobs.py", line 124, in download_jobs
    jobs_to_insert = [job for job in jobs if int(job['uid']) not in jobs_id]
  File "D:\Shapovalov\svoe\Python\PY\Parser6\2_download_jobs.py", line 124, in <listcomp>
    jobs_to_insert = [job for job in jobs if int(job['uid']) not in jobs_id]
KeyError: 'uid'

2023-09-06 06:32
Traceback (most recent call last):
  File "D:\Shapovalov\svoe\Python\PY\Parser6\2_download_jobs.py", line 128, in download_jobs
    ins_count, upd_count = db_operations.drop_to_db(jobs_to_insert, jobs_to_update)
  File "D:\Shapovalov\svoe\Python\PY\Parser6\db_operations.py", line 54, in drop_to_db
    with cursor.copy(f"COPY {table_name} ({columns}) FROM STDIN") as copy:
  File "d:\Shapovalov\svoe\Python\Python38\lib\contextlib.py", line 113, in __enter__
    return next(self.gen)
  File "D:\Shapovalov\svoe\Python\PY\Parser6\python\lib\site-packages\psycopg\cursor.py", line 916, in copy
    raise ex.with_traceback(None)
psycopg.errors.UndefinedColumn: column "createdon" of relation "upw_jobs" does not exist

2023-09-06 06:37
Traceback (most recent call last):
  File "D:\Shapovalov\svoe\Python\PY\Parser6\2_download_jobs.py", line 128, in download_jobs
    ins_count, upd_count = db_operations.drop_to_db(jobs_to_insert, jobs_to_update)
  File "D:\Shapovalov\svoe\Python\PY\Parser6\db_operations.py", line 56, in drop_to_db
    with cursor.copy(f"COPY {table_name} ({columns}) FROM STDIN") as copy:
  File "d:\Shapovalov\svoe\Python\Python38\lib\contextlib.py", line 113, in __enter__
    return next(self.gen)
  File "D:\Shapovalov\svoe\Python\PY\Parser6\python\lib\site-packages\psycopg\cursor.py", line 916, in copy
    raise ex.with_traceback(None)
psycopg.errors.UndefinedColumn: column "createdon" of relation "upw_jobs" does not exist

2023-09-06 06:41
Traceback (most recent call last):
  File "D:\Shapovalov\svoe\Python\PY\Parser6\2_download_jobs.py", line 128, in download_jobs
    ins_count, upd_count = db_operations.drop_to_db(jobs_to_insert, jobs_to_update)
  File "D:\Shapovalov\svoe\Python\PY\Parser6\db_operations.py", line 56, in drop_to_db
    with cursor.copy(f"COPY {table_name} (title, createdOn, type, ciphertext) FROM STDIN") as copy:
  File "d:\Shapovalov\svoe\Python\Python38\lib\contextlib.py", line 113, in __enter__
    return next(self.gen)
  File "D:\Shapovalov\svoe\Python\PY\Parser6\python\lib\site-packages\psycopg\cursor.py", line 916, in copy
    raise ex.with_traceback(None)
psycopg.errors.UndefinedColumn: column "createdon" of relation "upw_jobs" does not exist

2023-09-06 06:55
Traceback (most recent call last):
  File "D:\Shapovalov\svoe\Python\PY\Parser6\2_download_jobs.py", line 128, in download_jobs
    ins_count, upd_count = db_operations.drop_to_db(jobs_to_insert, jobs_to_update)
  File "D:\Shapovalov\svoe\Python\PY\Parser6\db_operations.py", line 57, in drop_to_db
    with cursor.copy(f"COPY {table_name} (title, createdOn, type, ciphertext) FROM STDIN") as copy:
  File "d:\Shapovalov\svoe\Python\Python38\lib\contextlib.py", line 113, in __enter__
    return next(self.gen)
  File "D:\Shapovalov\svoe\Python\PY\Parser6\python\lib\site-packages\psycopg\cursor.py", line 916, in copy
    raise ex.with_traceback(None)
psycopg.errors.UndefinedColumn: column "createdon" of relation "upw_jobs" does not exist

2023-09-06 06:59
Traceback (most recent call last):
  File "D:\Shapovalov\svoe\Python\PY\Parser6\2_download_jobs.py", line 128, in download_jobs
    ins_count, upd_count = db_operations.drop_to_db(jobs_to_insert, jobs_to_update)
  File "D:\Shapovalov\svoe\Python\PY\Parser6\db_operations.py", line 57, in drop_to_db
    with cursor.copy(f"COPY {table_name} (title, createdOn, type, ciphertext) FROM STDIN") as copy:
  File "d:\Shapovalov\svoe\Python\Python38\lib\contextlib.py", line 113, in __enter__
    return next(self.gen)
  File "D:\Shapovalov\svoe\Python\PY\Parser6\python\lib\site-packages\psycopg\cursor.py", line 916, in copy
    raise ex.with_traceback(None)
psycopg.errors.UndefinedColumn: column "createdon" of relation "upw_jobs" does not exist

2023-09-06 07:04
Traceback (most recent call last):
  File "D:\Shapovalov\svoe\Python\PY\Parser6\2_download_jobs.py", line 128, in download_jobs
    ins_count, upd_count = db_operations.drop_to_db(jobs_to_insert, jobs_to_update)
  File "D:\Shapovalov\svoe\Python\PY\Parser6\db_operations.py", line 57, in drop_to_db
    with cursor.copy(f"COPY {table_name} (title, createdOn, type, ciphertext) FROM STDIN") as copy:
  File "d:\Shapovalov\svoe\Python\Python38\lib\contextlib.py", line 113, in __enter__
    return next(self.gen)
  File "D:\Shapovalov\svoe\Python\PY\Parser6\python\lib\site-packages\psycopg\cursor.py", line 916, in copy
    raise ex.with_traceback(None)
psycopg.errors.UndefinedColumn: column "createdon" of relation "upw_jobs" does not exist

2023-09-06 07:08
Traceback (most recent call last):
  File "D:\Shapovalov\svoe\Python\PY\Parser6\2_download_jobs.py", line 128, in download_jobs
    ins_count, upd_count = db_operations.drop_to_db(jobs_to_insert, jobs_to_update)
  File "D:\Shapovalov\svoe\Python\PY\Parser6\db_operations.py", line 58, in drop_to_db
    with cursor.copy(query) as copy:
  File "d:\Shapovalov\svoe\Python\Python38\lib\contextlib.py", line 113, in __enter__
    return next(self.gen)
  File "D:\Shapovalov\svoe\Python\PY\Parser6\python\lib\site-packages\psycopg\cursor.py", line 916, in copy
    raise ex.with_traceback(None)
psycopg.errors.UndefinedColumn: column "createdon" of relation "upw_jobs" does not exist

2023-09-06 07:09
Traceback (most recent call last):
  File "D:\Shapovalov\svoe\Python\PY\Parser6\2_download_jobs.py", line 128, in download_jobs
    ins_count, upd_count = db_operations.drop_to_db(jobs_to_insert, jobs_to_update)
  File "D:\Shapovalov\svoe\Python\PY\Parser6\db_operations.py", line 58, in drop_to_db
    with cursor.copy(query) as copy:
  File "d:\Shapovalov\svoe\Python\Python38\lib\contextlib.py", line 113, in __enter__
    return next(self.gen)
  File "D:\Shapovalov\svoe\Python\PY\Parser6\python\lib\site-packages\psycopg\cursor.py", line 916, in copy
    raise ex.with_traceback(None)
psycopg.errors.UndefinedColumn: column "columns" of relation "upw_jobs" does not exist

2023-09-06 07:10
Traceback (most recent call last):
  File "D:\Shapovalov\svoe\Python\PY\Parser6\2_download_jobs.py", line 128, in download_jobs
    ins_count, upd_count = db_operations.drop_to_db(jobs_to_insert, jobs_to_update)
  File "D:\Shapovalov\svoe\Python\PY\Parser6\db_operations.py", line 61, in drop_to_db
    copy.write_row(record)
NameError: name 'record' is not defined

2023-09-06 07:12
Traceback (most recent call last):
  File "D:\Shapovalov\svoe\Python\PY\Parser6\2_download_jobs.py", line 128, in download_jobs
    ins_count, upd_count = db_operations.drop_to_db(jobs_to_insert, jobs_to_update)
  File "D:\Shapovalov\svoe\Python\PY\Parser6\db_operations.py", line 59, in drop_to_db
    copy.write_row(row)
  File "D:\Shapovalov\svoe\Python\PY\Parser6\python\lib\site-packages\psycopg\copy.py", line 307, in write_row
    data = self.formatter.write_row(row)
  File "D:\Shapovalov\svoe\Python\PY\Parser6\python\lib\site-packages\psycopg\copy.py", line 711, in write_row
    format_row_text(row, self.transformer, self._write_buffer)
  File "psycopg_binary\\_psycopg/copy.pyx", line 106, in psycopg_binary._psycopg.format_row_text
TypeError: object of type 'generator' has no len()

2023-09-06 07:13
Traceback (most recent call last):
  File "D:\Shapovalov\svoe\Python\PY\Parser6\2_download_jobs.py", line 128, in download_jobs
    ins_count, upd_count = db_operations.drop_to_db(jobs_to_insert, jobs_to_update)
  File "D:\Shapovalov\svoe\Python\PY\Parser6\db_operations.py", line 60, in drop_to_db
    copy.write_row(row)
  File "D:\Shapovalov\svoe\Python\PY\Parser6\python\lib\site-packages\psycopg\copy.py", line 307, in write_row
    data = self.formatter.write_row(row)
  File "D:\Shapovalov\svoe\Python\PY\Parser6\python\lib\site-packages\psycopg\copy.py", line 711, in write_row
    format_row_text(row, self.transformer, self._write_buffer)
  File "psycopg_binary\\_psycopg/copy.pyx", line 106, in psycopg_binary._psycopg.format_row_text
TypeError: object of type 'generator' has no len()

2023-09-06 07:14
Traceback (most recent call last):
  File "D:\Shapovalov\svoe\Python\PY\Parser6\2_download_jobs.py", line 128, in download_jobs
    ins_count, upd_count = db_operations.drop_to_db(jobs_to_insert, jobs_to_update)
  File "D:\Shapovalov\svoe\Python\PY\Parser6\db_operations.py", line 46, in drop_to_db
    job_values = [[job[key] for key in job_keys] for job in jobs_to_insert]
  File "D:\Shapovalov\svoe\Python\PY\Parser6\db_operations.py", line 46, in <listcomp>
    job_values = [[job[key] for key in job_keys] for job in jobs_to_insert]
  File "D:\Shapovalov\svoe\Python\PY\Parser6\db_operations.py", line 46, in <listcomp>
    job_values = [[job[key] for key in job_keys] for job in jobs_to_insert]
KeyError: '"title"'

2023-09-06 07:19
Traceback (most recent call last):
  File "D:\Shapovalov\svoe\Python\PY\Parser6\2_download_jobs.py", line 128, in download_jobs
    ins_count, upd_count = db_operations.drop_to_db(jobs_to_insert, jobs_to_update)
  File "D:\Shapovalov\svoe\Python\PY\Parser6\db_operations.py", line 62, in drop_to_db
    copy.write_row(row)
  File "d:\Shapovalov\svoe\Python\Python38\lib\contextlib.py", line 120, in __exit__
    next(self.gen)
  File "D:\Shapovalov\svoe\Python\PY\Parser6\python\lib\site-packages\psycopg\cursor.py", line 916, in copy
    raise ex.with_traceback(None)
psycopg.errors.InvalidTextRepresentation: invalid input syntax for integer: "f"
CONTEXT:  COPY upw_jobs, line 1, column enterpriseJob: "f"

2023-09-06 08:20
Traceback (most recent call last):
  File "D:\Shapovalov\svoe\Python\PY\Parser6\2_download_jobs.py", line 128, in download_jobs
    ins_count, upd_count = db_operations.drop_to_db(jobs_to_insert, jobs_to_update)
  File "D:\Shapovalov\svoe\Python\PY\Parser6\db_operations.py", line 62, in drop_to_db
    copy.write_row(row)
  File "d:\Shapovalov\svoe\Python\Python38\lib\contextlib.py", line 120, in __exit__
    next(self.gen)
  File "D:\Shapovalov\svoe\Python\PY\Parser6\python\lib\site-packages\psycopg\cursor.py", line 916, in copy
    raise ex.with_traceback(None)
psycopg.errors.InvalidTextRepresentation: invalid input syntax for integer: "f"
CONTEXT:  COPY upw_jobs, line 1, column enterpriseJob: "f"

2023-09-06 08:33
Traceback (most recent call last):
  File "D:\Shapovalov\svoe\Python\PY\Parser6\2_download_jobs.py", line 133, in download_jobs
    ins_count, upd_count = db_operations.drop_to_db(jobs_to_insert, jobs_to_update)
  File "D:\Shapovalov\svoe\Python\PY\Parser6\db_operations.py", line 62, in drop_to_db
    copy.write_row(row)
  File "d:\Shapovalov\svoe\Python\Python38\lib\contextlib.py", line 120, in __exit__
    next(self.gen)
  File "D:\Shapovalov\svoe\Python\PY\Parser6\python\lib\site-packages\psycopg\cursor.py", line 916, in copy
    raise ex.with_traceback(None)
psycopg.errors.InvalidTextRepresentation: invalid input syntax for integer: "f"
CONTEXT:  COPY upw_jobs, line 1, column premium: "f"

2023-09-06 08:53
Traceback (most recent call last):
  File "D:\Shapovalov\svoe\Python\PY\Parser6\2_download_jobs.py", line 139, in download_jobs
    self.Savereq_list(req_list)
NameError: name 'self' is not defined

2023-09-06 10:15
Traceback (most recent call last):
  File "D:\Shapovalov\svoe\Python\PY\Parser6\2_download_jobs.py", line 109, in download_jobs
    ins_count, upd_count = db_operations.drop_to_db(jobs_to_insert, jobs_to_update)
  File "D:\Shapovalov\svoe\Python\PY\Parser6\db_operations.py", line 72, in drop_to_db
    job_keys = list(jobs_to_update[0].keys())
IndexError: list index out of range

2023-09-06 19:17
Traceback (most recent call last):
  File "D:\Shapovalov\svoe\Python\PY\Parser6\2_download_jobs.py", line 108, in download_jobs
    ins_count, upd_count, new_id = db_operations.drop_to_db(jobs, jobs_id)
  File "D:\Shapovalov\svoe\Python\PY\Parser6\db_operations.py", line 65, in drop_to_db
    curs.execute(
UnboundLocalError: local variable 'curs' referenced before assignment

2023-09-06 19:18
Traceback (most recent call last):
  File "D:\Shapovalov\svoe\Python\PY\Parser6\2_download_jobs.py", line 108, in download_jobs
    ins_count, upd_count, new_id = db_operations.drop_to_db(jobs, jobs_id)
  File "D:\Shapovalov\svoe\Python\PY\Parser6\db_operations.py", line 65, in drop_to_db
    curs = conn.curssor()
AttributeError: 'Connection' object has no attribute 'curssor'

2023-09-06 19:19
Traceback (most recent call last):
  File "D:\Shapovalov\svoe\Python\PY\Parser6\2_download_jobs.py", line 108, in download_jobs
    ins_count, upd_count, new_id = db_operations.drop_to_db(jobs, jobs_id)
  File "D:\Shapovalov\svoe\Python\PY\Parser6\db_operations.py", line 73, in drop_to_db
    ins_count = len(jobs_to_insert)
NameError: name 'jobs_to_insert' is not defined

2023-09-06 19:21
Traceback (most recent call last):
  File "D:\Shapovalov\svoe\Python\PY\Parser6\2_download_jobs.py", line 108, in download_jobs
    ins_count, upd_count, new_id = db_operations.drop_to_db(jobs, jobs_id)
  File "D:\Shapovalov\svoe\Python\PY\Parser6\db_operations.py", line 170, in drop_to_db
    return ins_count, upd_count, new_id
NameError: name 'ins_count' is not defined

2023-09-06 19:25
Traceback (most recent call last):
  File "D:\Shapovalov\svoe\Python\PY\Parser6\2_download_jobs.py", line 108, in download_jobs
    ins_count, upd_count, new_id = db_operations.drop_to_db(jobs, jobs_id)
  File "D:\Shapovalov\svoe\Python\PY\Parser6\db_operations.py", line 162, in drop_to_db
    return 0, 0, new_id
NameError: name 'new_id' is not defined

2023-09-06 19:46
Traceback (most recent call last):
  File "D:\Shapovalov\svoe\Python\PY\Parser6\2_download_jobs.py", line 108, in download_jobs
    ins_count, upd_count, new_id = db_operations.drop_to_db(jobs, jobs_id)
  File "D:\Shapovalov\svoe\Python\PY\Parser6\db_operations.py", line 62, in drop_to_db
    placeholders = ['%s']*len(columns).join(', ')
AttributeError: 'int' object has no attribute 'join'

2023-09-06 19:47
Traceback (most recent call last):
  File "D:\Shapovalov\svoe\Python\PY\Parser6\2_download_jobs.py", line 108, in download_jobs
    ins_count, upd_count, new_id = db_operations.drop_to_db(jobs, jobs_id)
  File "D:\Shapovalov\svoe\Python\PY\Parser6\db_operations.py", line 62, in drop_to_db
    placeholders = (['%s']*len(columns)).join(', ')
AttributeError: 'list' object has no attribute 'join'

2023-09-06 19:47
Traceback (most recent call last):
  File "D:\Shapovalov\svoe\Python\PY\Parser6\2_download_jobs.py", line 113, in download_jobs
    jobs_id.extend(new_id)
TypeError: 'int' object is not iterable

2023-09-06 19:59
Traceback (most recent call last):
  File "D:\Shapovalov\svoe\Python\PY\Parser6\2_download_jobs.py", line 108, in download_jobs
    ins_count, upd_count, new_id = db_operations.drop_to_db(jobs, jobs_id)
  File "D:\Shapovalov\svoe\Python\PY\Parser6\db_operations.py", line 54, in drop_to_db
    curs.execute("SELECT * FROM {table_name} LIMIT 0;")
  File "D:\Shapovalov\svoe\Python\PY\Parser6\python\lib\site-packages\psycopg\cursor.py", line 737, in execute
    raise ex.with_traceback(None)
psycopg.errors.SyntaxError: syntax error at or near "{"
LINE 1: SELECT * FROM {table_name} LIMIT 0;
                      ^

2023-09-06 20:01
Traceback (most recent call last):
  File "D:\Shapovalov\svoe\Python\PY\Parser6\2_download_jobs.py", line 113, in download_jobs
    jobs_id.extend(new_id)
TypeError: 'int' object is not iterable

2023-09-06 20:03
Traceback (most recent call last):
  File "D:\Shapovalov\svoe\Python\PY\Parser6\2_download_jobs.py", line 113, in download_jobs
    jobs_id.extend(new_id)
TypeError: 'int' object is not iterable

2023-09-06 20:05
Traceback (most recent call last):
  File "D:\Shapovalov\svoe\Python\PY\Parser6\2_download_jobs.py", line 113, in download_jobs
    jobs_id.extend(new_id)
TypeError: 'int' object is not iterable

2023-09-06 20:09
Traceback (most recent call last):
  File "D:\Shapovalov\svoe\Python\PY\Parser6\2_download_jobs.py", line 113, in download_jobs
    jobs_id.extend(new_id)
TypeError: 'int' object is not iterable

2023-09-06 20:12
Traceback (most recent call last):
  File "D:\Shapovalov\svoe\Python\PY\Parser6\2_download_jobs.py", line 113, in download_jobs
    jobs_id.extend(new_id)
TypeError: 'int' object is not iterable

2023-09-07 05:46
Traceback (most recent call last):
  File "D:\Shapovalov\svoe\Python\PY\Parser6\2_download_jobs.py", line 113, in download_jobs
    jobs_id.extend(new_id)
TypeError: 'int' object is not iterable

2023-09-07 08:55
Traceback (most recent call last):
  File "D:\Shapovalov\svoe\Python\PY\Parser6\2_download_jobs.py", line 108, in download_jobs
    ins_count, upd_count, new_id = db_operations.drop_to_db(jobs, jobs_id)
  File "D:\Shapovalov\svoe\Python\PY\Parser6\db_operations.py", line 66, in drop_to_db
    print(values_to_insert[0])
IndexError: list index out of range

2023-09-07 08:56
Traceback (most recent call last):
  File "D:\Shapovalov\svoe\Python\PY\Parser6\2_download_jobs.py", line 113, in download_jobs
    jobs_id.extend(new_id)
TypeError: 'int' object is not iterable

2023-09-07 09:17
Traceback (most recent call last):
  File "D:\Shapovalov\svoe\Python\PY\Parser6\2_download_jobs.py", line 113, in download_jobs
    jobs_id.extend(new_id)
TypeError: 'int' object is not iterable

2023-09-07 09:18
Traceback (most recent call last):
  File "D:\Shapovalov\svoe\Python\PY\Parser6\db_operations.py", line 108, in drop_to_db
    curs.executemany(query, values_to_update)
  File "D:\Shapovalov\svoe\Python\PY\Parser6\python\lib\site-packages\psycopg\cursor.py", line 772, in executemany
    raise ex.with_traceback(None)
psycopg.ProgrammingError: the query has 0 placeholders but 47 parameters were passed

During handling of the above exception, another exception occurred:

Traceback (most recent call last):
  File "D:\Shapovalov\svoe\Python\PY\Parser6\2_download_jobs.py", line 108, in download_jobs
    ins_count, upd_count, new_id = db_operations.drop_to_db(jobs, jobs_id)
  File "D:\Shapovalov\svoe\Python\PY\Parser6\db_operations.py", line 118, in drop_to_db
    except (Ecxeption, psycopg.Error) as e:
NameError: name 'Ecxeption' is not defined

2023-09-07 09:19
Traceback (most recent call last):
  File "D:\Shapovalov\svoe\Python\PY\Parser6\2_download_jobs.py", line 113, in download_jobs
    jobs_id.extend(new_id)
TypeError: 'int' object is not iterable

2023-09-07 09:40
Traceback (most recent call last):
  File "D:\Shapovalov\svoe\Python\PY\Parser6\2_download_jobs.py", line 113, in download_jobs
    jobs_id.extend(new_id)
TypeError: 'int' object is not iterable

2023-09-07 09:43
Traceback (most recent call last):
  File "D:\Shapovalov\svoe\Python\PY\Parser6\2_download_jobs.py", line 113, in download_jobs
    jobs_id.extend(new_id)
TypeError: 'int' object is not iterable

2023-09-07 09:44
Traceback (most recent call last):
  File "D:\Shapovalov\svoe\Python\PY\Parser6\2_download_jobs.py", line 113, in download_jobs
    jobs_id.extend(new_id)
TypeError: 'int' object is not iterable

2023-09-07 09:45
Traceback (most recent call last):
  File "D:\Shapovalov\svoe\Python\PY\Parser6\2_download_jobs.py", line 113, in download_jobs
    jobs_id.extend(new_id)
TypeError: 'int' object is not iterable

2023-09-07 10:04
Traceback (most recent call last):
  File "D:\Shapovalov\svoe\Python\PY\Parser6\2_download_jobs.py", line 113, in download_jobs
    jobs_id.extend(new_id)
TypeError: 'int' object is not iterable

2023-09-07 10:17
Traceback (most recent call last):
  File "D:\Shapovalov\svoe\Python\PY\Parser6\2_download_jobs.py", line 113, in download_jobs
    jobs_id.extend(new_id)
TypeError: 'int' object is not iterable

2023-09-07 10:20
Traceback (most recent call last):
  File "D:\Shapovalov\svoe\Python\PY\Parser6\2_download_jobs.py", line 113, in download_jobs
    jobs_id.extend(new_id)
TypeError: 'int' object is not iterable

2023-09-07 10:23
Traceback (most recent call last):
  File "D:\Shapovalov\svoe\Python\PY\Parser6\2_download_jobs.py", line 113, in download_jobs
    jobs_id.extend(new_id)
TypeError: 'int' object is not iterable

2023-09-07 10:27
Traceback (most recent call last):
  File "D:\Shapovalov\svoe\Python\PY\Parser6\2_download_jobs.py", line 113, in download_jobs
    jobs_id.extend(new_id)
TypeError: 'int' object is not iterable

2023-09-07 10:37
Traceback (most recent call last):
  File "D:\Shapovalov\svoe\Python\PY\Parser6\2_download_jobs.py", line 113, in download_jobs
    jobs_id.extend(new_id)
TypeError: 'int' object is not iterable

2023-09-07 10:37
Traceback (most recent call last):
  File "D:\Shapovalov\svoe\Python\PY\Parser6\2_download_jobs.py", line 113, in download_jobs
    jobs_id.extend(new_id)
TypeError: 'int' object is not iterable

2023-09-07 10:40
Traceback (most recent call last):
  File "D:\Shapovalov\svoe\Python\PY\Parser6\2_download_jobs.py", line 113, in download_jobs
    jobs_id.extend(new_id)
TypeError: 'int' object is not iterable

2023-09-07 10:49
Traceback (most recent call last):
  File "D:\Shapovalov\svoe\Python\PY\Parser6\2_download_jobs.py", line 108, in download_jobs
    ins_count, upd_count, new_id = db_operations.drop_to_db(jobs, jobs_id)
  File "D:\Shapovalov\svoe\Python\PY\Parser6\db_operations.py", line 120, in drop_to_db
    insert()
NameError: name 'insert' is not defined

2023-09-07 10:54
Traceback (most recent call last):
  File "D:\Shapovalov\svoe\Python\PY\Parser6\2_download_jobs.py", line 108, in download_jobs
    ins_count, upd_count, new_id = db_operations.drop_to_db(jobs, jobs_id)
  File "D:\Shapovalov\svoe\Python\PY\Parser6\db_operations.py", line 119, in drop_to_db
    set_id = f'id=%{columns.index(id)+1}'
ValueError: <built-in function id> is not in list

2023-09-07 10:55
Traceback (most recent call last):
  File "D:\Shapovalov\svoe\Python\PY\Parser6\2_download_jobs.py", line 113, in download_jobs
    jobs_id.extend(new_id)
TypeError: 'int' object is not iterable

2023-09-07 10:57
Traceback (most recent call last):
  File "D:\Shapovalov\svoe\Python\PY\Parser6\2_download_jobs.py", line 113, in download_jobs
    jobs_id.extend(new_id)
TypeError: 'int' object is not iterable

2023-09-07 10:59
Traceback (most recent call last):
  File "D:\Shapovalov\svoe\Python\PY\Parser6\2_download_jobs.py", line 113, in download_jobs
    jobs_id.extend(new_id)
TypeError: 'int' object is not iterable

2023-09-07 11:00
Traceback (most recent call last):
  File "D:\Shapovalov\svoe\Python\PY\Parser6\2_download_jobs.py", line 113, in download_jobs
    jobs_id.extend(new_id)
TypeError: 'int' object is not iterable

2023-09-07 18:37
Traceback (most recent call last):
  File "D:\Shapovalov\svoe\Python\PY\Parser6\2_download_jobs.py", line 113, in download_jobs
    jobs_id.extend(new_id)
TypeError: 'int' object is not iterable

2023-09-07 18:39
Traceback (most recent call last):
  File "D:\Shapovalov\svoe\Python\PY\Parser6\2_download_jobs.py", line 113, in download_jobs
    jobs_id.extend(new_id)
TypeError: 'int' object is not iterable

2023-09-07 18:41
Traceback (most recent call last):
  File "D:\Shapovalov\svoe\Python\PY\Parser6\2_download_jobs.py", line 113, in download_jobs
    jobs_id.extend(new_id)
TypeError: 'int' object is not iterable

2023-09-07 18:52
Traceback (most recent call last):
  File "D:\Shapovalov\svoe\Python\PY\Parser6\2_download_jobs.py", line 113, in download_jobs
    jobs_id.extend(new_id)
TypeError: 'int' object is not iterable

2023-09-07 18:53
Traceback (most recent call last):
  File "D:\Shapovalov\svoe\Python\PY\Parser6\2_download_jobs.py", line 113, in download_jobs
    jobs_id.extend(new_id)
TypeError: 'int' object is not iterable

2023-09-07 18:56
Traceback (most recent call last):
  File "D:\Shapovalov\svoe\Python\PY\Parser6\2_download_jobs.py", line 113, in download_jobs
    jobs_id.extend(new_id)
TypeError: 'int' object is not iterable

2023-09-07 19:01
Traceback (most recent call last):
  File "D:\Shapovalov\svoe\Python\PY\Parser6\2_download_jobs.py", line 93, in download_jobs
    jobs_id = db_operations.id_from_db()
  File "D:\Shapovalov\svoe\Python\PY\Parser6\db_operations.py", line 29, in id_from_db
    curs.execute(f"SELECT id FROM %s;", table_name)
  File "D:\Shapovalov\svoe\Python\PY\Parser6\python\lib\site-packages\psycopg\cursor.py", line 733, in execute
    self._conn.wait(
  File "D:\Shapovalov\svoe\Python\PY\Parser6\python\lib\site-packages\psycopg\connection.py", line 958, in wait
    return waiting.wait(gen, self.pgconn.socket, timeout=timeout)
  File "psycopg_binary\\_psycopg/waiting.pyx", line 191, in psycopg_binary._psycopg.wait_c
  File "D:\Shapovalov\svoe\Python\PY\Parser6\python\lib\site-packages\psycopg\cursor.py", line 209, in _execute_gen
    pgq = self._convert_query(query, params)
  File "D:\Shapovalov\svoe\Python\PY\Parser6\python\lib\site-packages\psycopg\cursor.py", line 482, in _convert_query
    pgq.convert(query, params)
  File "D:\Shapovalov\svoe\Python\PY\Parser6\python\lib\site-packages\psycopg\_queries.py", line 80, in convert
    self.dump(vars)
  File "D:\Shapovalov\svoe\Python\PY\Parser6\python\lib\site-packages\psycopg\_queries.py", line 89, in dump
    params = _validate_and_reorder_params(self._parts, vars, self._order)
  File "D:\Shapovalov\svoe\Python\PY\Parser6\python\lib\site-packages\psycopg\_queries.py", line 253, in _validate_and_reorder_params
    raise TypeError(
TypeError: query parameters should be a sequence or a mapping, got str

2023-09-07 19:02
Traceback (most recent call last):
  File "D:\Shapovalov\svoe\Python\PY\Parser6\2_download_jobs.py", line 93, in download_jobs
    jobs_id = db_operations.id_from_db()
  File "D:\Shapovalov\svoe\Python\PY\Parser6\db_operations.py", line 29, in id_from_db
    curs.execute(f"SELECT id FROM %s;", (table_name,))
  File "D:\Shapovalov\svoe\Python\PY\Parser6\python\lib\site-packages\psycopg\cursor.py", line 737, in execute
    raise ex.with_traceback(None)
psycopg.errors.SyntaxError: syntax error at or near "$1"
LINE 1: SELECT id FROM $1;
                       ^

2023-09-07 19:03
Traceback (most recent call last):
  File "D:\Shapovalov\svoe\Python\PY\Parser6\2_download_jobs.py", line 93, in download_jobs
    jobs_id = db_operations.id_from_db()
  File "D:\Shapovalov\svoe\Python\PY\Parser6\db_operations.py", line 29, in id_from_db
    curs.execute(f"SELECT id FROM $1;", (table_name,))
  File "D:\Shapovalov\svoe\Python\PY\Parser6\python\lib\site-packages\psycopg\cursor.py", line 737, in execute
    raise ex.with_traceback(None)
psycopg.ProgrammingError: the query has 0 placeholders but 1 parameters were passed

2023-09-07 19:04
Traceback (most recent call last):
  File "D:\Shapovalov\svoe\Python\PY\Parser6\2_download_jobs.py", line 93, in download_jobs
    jobs_id = db_operations.id_from_db()
  File "D:\Shapovalov\svoe\Python\PY\Parser6\db_operations.py", line 29, in id_from_db
    curs.execute(f"SELECT id FROM %S;", (table_name,))
  File "D:\Shapovalov\svoe\Python\PY\Parser6\python\lib\site-packages\psycopg\cursor.py", line 737, in execute
    raise ex.with_traceback(None)
psycopg.ProgrammingError: only '%s', '%b', '%t' are allowed as placeholders, got '%S'

2023-09-07 19:04
Traceback (most recent call last):
  File "D:\Shapovalov\svoe\Python\PY\Parser6\2_download_jobs.py", line 93, in download_jobs
    jobs_id = db_operations.id_from_db()
  File "D:\Shapovalov\svoe\Python\PY\Parser6\db_operations.py", line 29, in id_from_db
    curs.execute(f"SELECT id FROM %s;", (table_name,))
  File "D:\Shapovalov\svoe\Python\PY\Parser6\python\lib\site-packages\psycopg\cursor.py", line 737, in execute
    raise ex.with_traceback(None)
psycopg.errors.SyntaxError: syntax error at or near "$1"
LINE 1: SELECT id FROM $1;
                       ^

2023-09-07 19:05
Traceback (most recent call last):
  File "D:\Shapovalov\svoe\Python\PY\Parser6\2_download_jobs.py", line 93, in download_jobs
    jobs_id = db_operations.id_from_db()
  File "D:\Shapovalov\svoe\Python\PY\Parser6\db_operations.py", line 29, in id_from_db
    curs.execute("SELECT id FROM %s;", (table_name,))
  File "D:\Shapovalov\svoe\Python\PY\Parser6\python\lib\site-packages\psycopg\cursor.py", line 737, in execute
    raise ex.with_traceback(None)
psycopg.errors.SyntaxError: syntax error at or near "$1"
LINE 1: SELECT id FROM $1;
                       ^

2023-09-07 19:05
Traceback (most recent call last):
  File "D:\Shapovalov\svoe\Python\PY\Parser6\2_download_jobs.py", line 93, in download_jobs
    jobs_id = db_operations.id_from_db()
  File "D:\Shapovalov\svoe\Python\PY\Parser6\db_operations.py", line 29, in id_from_db
    curs.execute("SELECT id FROM %s;", (table_name))
  File "D:\Shapovalov\svoe\Python\PY\Parser6\python\lib\site-packages\psycopg\cursor.py", line 733, in execute
    self._conn.wait(
  File "D:\Shapovalov\svoe\Python\PY\Parser6\python\lib\site-packages\psycopg\connection.py", line 958, in wait
    return waiting.wait(gen, self.pgconn.socket, timeout=timeout)
  File "psycopg_binary\\_psycopg/waiting.pyx", line 191, in psycopg_binary._psycopg.wait_c
  File "D:\Shapovalov\svoe\Python\PY\Parser6\python\lib\site-packages\psycopg\cursor.py", line 209, in _execute_gen
    pgq = self._convert_query(query, params)
  File "D:\Shapovalov\svoe\Python\PY\Parser6\python\lib\site-packages\psycopg\cursor.py", line 482, in _convert_query
    pgq.convert(query, params)
  File "D:\Shapovalov\svoe\Python\PY\Parser6\python\lib\site-packages\psycopg\_queries.py", line 80, in convert
    self.dump(vars)
  File "D:\Shapovalov\svoe\Python\PY\Parser6\python\lib\site-packages\psycopg\_queries.py", line 89, in dump
    params = _validate_and_reorder_params(self._parts, vars, self._order)
  File "D:\Shapovalov\svoe\Python\PY\Parser6\python\lib\site-packages\psycopg\_queries.py", line 253, in _validate_and_reorder_params
    raise TypeError(
TypeError: query parameters should be a sequence or a mapping, got str

2023-09-07 19:26
Traceback (most recent call last):
  File "D:\Shapovalov\svoe\Python\PY\Parser6\2_download_jobs.py", line 113, in download_jobs
    jobs_id.extend(new_id)
TypeError: 'int' object is not iterable

2023-09-07 19:27
Traceback (most recent call last):
  File "D:\Shapovalov\svoe\Python\PY\Parser6\2_download_jobs.py", line 113, in download_jobs
    jobs_id.extend(new_id)
TypeError: 'int' object is not iterable

2023-09-07 19:28
Traceback (most recent call last):
  File "D:\Shapovalov\svoe\Python\PY\Parser6\2_download_jobs.py", line 113, in download_jobs
    jobs_id.extend(new_id)
TypeError: 'int' object is not iterable

2023-09-07 19:29
Traceback (most recent call last):
  File "D:\Shapovalov\svoe\Python\PY\Parser6\2_download_jobs.py", line 113, in download_jobs
    jobs_id.extend(new_id)
TypeError: 'int' object is not iterable

2023-09-07 19:48
Traceback (most recent call last):
  File "D:\Shapovalov\svoe\Python\PY\Parser6\2_download_jobs.py", line 93, in download_jobs
    jobs_id = db_operations.id_from_db()
  File "D:\Shapovalov\svoe\Python\PY\Parser6\db_operations.py", line 36, in id_from_db
    result = curs.execute(f"SELECT id FROM {table_name};").fetchall()
NameError: name 'curs' is not defined

2023-09-07 19:53
Traceback (most recent call last):
  File "D:\Shapovalov\svoe\Python\PY\Parser6\2_download_jobs.py", line 108, in download_jobs
    ins_count, upd_count, new_id = db_operations.drop_to_db(jobs, jobs_id)
  File "D:\Shapovalov\svoe\Python\PY\Parser6\db_operations.py", line 48, in drop_to_db
    col = col_names_from_db()
  File "D:\Shapovalov\svoe\Python\PY\Parser6\db_operations.py", line 43, in col_names_from_db
    columns = [desc[0] for desc in curs.description]
TypeError: 'NoneType' object is not iterable

2023-09-07 20:13
1
2023-09-07 20:13
1
